Workbook
Name Annual_Depreciation_Tanker: 'Tanker Schedule'!$B$9
Name Base_NG_Demand: Inputs!$F$42:$F$42
Name Building_Cost_Pipeline: Inputs!$B$42
Name Building_Cost_Tanker: Inputs!$B$58
Name Carbon_Offset_Tanker: Inputs!$B$69
Name Contract_Mgmt_Fees: Inputs!$B$43
Name Conv_Factor: Inputs!$F$58:$F$58
Name D_i_Y: Inputs!$B$16
Name Days_Apr: Inputs!$B$28:$B$28
Name Days_Aug: Inputs!$B$32:$B$32
Name Days_Dec: Inputs!$B$36:$B$36
Name Days_Feb: Inputs!$B$26:$B$26
Name Days_Jan: Inputs!$B$25:$B$25
Name Days_Jul: Inputs!$B$31:$B$31
Name Days_Jun: Inputs!$B$30:$B$30
Name Days_Mar: Inputs!$B$27:$B$27
Name Days_May: Inputs!$B$29:$B$29
Name Days_Nov: Inputs!$B$35:$B$35
Name Days_Oct: Inputs!$B$34:$B$34
Name Days_Sept: Inputs!$B$33:$B$33
Name Demand_Increase: Inputs!$F$18
Name Discount_Rate: Inputs!$F$23
Name Employee_Deduction_Rate: Inputs!$B$75:$B$75
Name Employer_Social_Insurance_Rate: Inputs!$B$74:$B$74
Name First_Yr: Inputs!$B$19:$B$19
Name Fuel_Pipeline: Inputs!$B$51
Name General_Main_Eng: Inputs!$B$50:$B$50
Name General_Pipeline: Inputs!$B$52
Name General_Tanker: Inputs!$B$63
Name Heavy_Fuel_Oil: Inputs!$B$66
Name Increment: Inputs!$B$14
Name Inflation_Annual: Inputs!$F$15
Name Inflation_Carbon_Offset: Inputs!$F$16
Name Insurance_Cov: Inputs!$F$65:$F$65
Name Insurance_Pipeline: Inputs!$B$48
Name Insurance_Tanker: Inputs!$B$62
Name LNG_Tanker_Cap: Inputs!$F$62:$F$62
Name Loan_Payment_Term: Inputs!$F$22
Name M_i_Y: Inputs!$B$15
Name Min_Cash_Balance: Inputs!$F$24
Name Nil: Inputs!$F$19:$F$19
Name Operating_Exp: Inputs!$B$68
Name Operations_Mgmt: Inputs!$B$49
Name Pipeline_TotalCost: Inputs!$B$44:$B$44
Name Port_Fees: Inputs!$B$65
Name Purch_price_LNG: Inputs!$F$60:$F$60
Name Purch_price_NG: Inputs!$F$43:$F$43
Name Salvage_Val_Pipeline: Inputs!$B$45
Name Salvage_Val_Tanker: Inputs!$B$59
Name SBU_Insurance: Inputs!$F$66:$F$66
Name Sell_price_LNG: Inputs!$F$61:$F$61
Name Sell_price_NG: Inputs!$F$44:$F$44
Name Set_Up_Year: Inputs!$B$17
Name Stores_Spares_Lube: Inputs!$B$64
Name Tons_Req_a_Trip: Inputs!$B$67
Name Total_Crew_Costs: Inputs!$B$72
Name Total_Years: Inputs!$B$20:$B$20
Name Useful_Life: Inputs!$F$27
Name Y3_Port_Repair: Inputs!$F$64:$F$64
Name Y5_Carbon_Increase: Inputs!$F$17:$F$17

Sheet Cover Page
D1: DATA MODEL: QATAR ENERGY CASE
A3: Business Proposition:
A4: Qatar Energy aims to deliver a cost-effective, financially advantageous method for supplying natural gas to Bahrain over a 30-year period. Using our financial model, we can compare the trade-off between the high up-front capital cost of the pipeline ($520 million) and the operational flexibility of the Q-Max LNG Tanker ($250 million). The goal is to maximize shareholder wealth by selecting the delivery method (i.e., Pipeline or Tanker) that offers the highest capital efficiency and other return metrics, ensuring that these returns exceed the 4% cost of capital provided by the National Bank of Qatar.
A10: Executive Summary:
A11: Based on our 30-year competitive financial analysis, the Q-Max Tanker (LNG) is the recommended delivery method. When comparing the 30-year NPV, it outperforms the pipeline across our primary financial metrics, offering higher wealth and faster capital recovery for investors.
A15: Strategeic Financial Findings (Pipeline vs. Tanker)
D16: Pipeline (NG) | F16: Tanker (LNG)
A17: NPV | D17: ='NPV (Y2-Y31)'!D78 -> 1.6938693e+09 | F17: ='NPV (Y2-Y31)'!F78 -> 1.980071e+09
A18: IRR | D18: =IRR('NPV (Y2-Y31)'!C47:C77) -> 0.1852723 | F18: =IRR('NPV (Y2-Y31)'!E47:E77) -> 0.40670795
A19: Payback Period | D19: {=(Set_Up_Year+Increment+Increment+Increment+Increment)+(Pipeline_TotalCost-SUM('NPV (Y2-Y31)'!C48:C52))/'NPV (Y2-Y31)'!C53} -> 5.7243897 | F19: =(Set_Up_Year+Increment)+(Building_Cost_Tanker-'NPV (Y2-Y31)'!E48-'NPV (Y2-Y31)'!E49)/'NPV (Y2-Y31)'!E50 -> 2.5157507
A20: Profitability Index (PI) | D20: {='NPV (Y2-Y31)'!D78/Pipeline_TotalCost} -> 3.257441 | F20: ='NPV (Y2-Y31)'!F78/Building_Cost_Tanker -> 7.9202841
A22: Key Insights & Risks
A23: Operational Resilience: In Year 3, the port damage was 90% covered by insurance, therefore, an additional $500,000 to repair the port had to be paid by Qatar Energy. Despite the port damage, net income increased from Year 2 of ~80 million to Year 3 of ~81 million. Additionally, with carbon costs doubling in Year 5 to over $74 million, the Tanker remains highly profitable, with Net Income in Year 5 of ~47 million. Confirming these situations indicates our model can withstand economic shifts without threatening the project's success.
A27: Cash Position: By the end of Year 5, the Tanker generates an ending cash balance of $368,806,012, which exceeds the required $10 million minimum reserve.
A29: Capital Efficiency (PI & IRR): The tanker requires an initial capital of 250 million, which is 52% less than the Pipeline's initial investment of $520 millipn. The tanker method provides a PI of 7.92 (compared to the pipeline PI of 3.26), indicating it is twice as efficient an investment and would provide a 7.92x return per dollar.
A32: Wealth (NPV): The tanker (NPV of 1,980,071,025) creates $286,201,680 more in total NPV (of 1,693,869,345) than the pipeline, due to its lower initial investment and the favourable price-to-volume ratio of LNG.
A34: Cash Recovery (Payback): The tanker reaches a break-even point in 2.52 years of operations, whereas the pipeline takes 5.72 years, representing significantly lower/higher capital-lockup risk.
A36: Recomendation:
A37: It is recommended that Qatar Energy proceed with the Q-Max Tanker delivery method. It offers higher NPV and PI, indicating that Qatar Energy maximizes the value of its sovereign natural gas assets while maintaining superior liquidity and capital flexibility.

Sheet Inputs
A1: QATAR ENERGY
A2: INPUTS - PIPELINE & TANKER
A4: Color Key
A5: Black = Scaffolding, calculated values (do not overwrite)
A6: Red = Editable data
A7: Black on blue = Owner's decision
B8: Grey shade - no input
A9: Green = Calculated value, do not overwrite
A11: GENERAL AND SHARED INPUTS
A13: TIME AND DATE | E13: ECONOMICS
A14: Increment | B14: 1 | E14: Inflations (compounded):
A15: Months in Year | B15: 12 | E15: Annual Inflation | F15: 0.015
A16: Days in Year | B16: 365.25 | E16: Carbon Offset Inflation | F16: 0.039
A17: Set Up Year | B17: 1 | E17: Carbon Offset Inflation (Special - Year 5) | F17: 2
E18: Demand Increase Rate | F18: 0.005
A19: First Year of Ops | B19: 2 | E19: Nil | F19: 0
A20: Total Years of Ops | B20: 30
A21: Billing Day | B21: 21 | E21: FINANCE
A22: Dormant Months Y1 | B22: 1 | E22: Loan Payment Term (year) | F22: 30
E23: Discount Rate (compounded annually) | F23: 0.04
A24: Days in Month | E24: Minimum Cash Balance | F24: 10000000
A25: January | B25: 31
A26: February | B26: 28.25 | E26: CAPITAL ASSETS
A27: March | B27: 31 | E27: Useful Life (years) | F27: 30
A28: April | B28: 30
A29: May | B29: 31
A30: June | B30: 30
A31: July | B31: 31
A32: August | B32: 31
A33: September | B33: 30
A34: October | B34: 31
A35: November | B35: 30
A36: December | B36: 31
A39: PIPELINE INPUTS
A41: CAPITAL ASSETS | E41: PRICING, DEMAND AND SUPPLIES
A42: Pipeline Building Cost | B42: 400000000 | E42: Base NG Demand (annual, starting Y2) | F42: 17000000000
A43: Contract Management Fees | B43: 120000000 | E43: NG Purchase price, per cubic meter | F43: 0.046
A44: Total Pipeline Cost | B44: =Contract_Mgmt_Fees+Building_Cost_Pipeline -> 520000000 | E44: NG Selling price, per cubic meter | F44: 0.052
A45: Pipeline Salvage Value (net of decommissioning costs, Y31) | B45: 15000000
A47: INFLATABLE COSTS
...

Sheet Pipeline Schedule
A1: QATAR ENERGY
A2: PIPELINE SCHEDULE
A4: CAPITAL ASSETS
B5: Pipeline
A6: Capital Assets | B6: {=Pipeline_TotalCost} -> 520000000
A7: Useful Life | B7: =Useful_Life -> 30
A8: Salvage value | B8: =Salvage_Val_Pipeline -> 15000000
A9: Annual Depreciation | B9: {=(Pipeline_TotalCost-Salvage_Val_Pipeline)/Useful_Life} -> 16833333
A11: DEPRECIATION
A12: Year | B12: Begininng Value ($) | C12: Depreciation Amount ($) | D12: Remaining Amount ($)
A13: =Increment -> 1
A14: =A13+Increment -> 2 | B14: {=Pipeline_TotalCost} -> 520000000 | C14: =$B$9 -> 16833333 | D14: =B14-C14 -> 5.0316667e+08
A15: =A14+Increment -> 3 | B15: =D14 -> 5.0316667e+08 | C15: =$B$9 -> 16833333 | D15: =B15-C15 -> 4.8633333e+08
A16: =A15+Increment -> 4 | B16: =D15 -> 4.8633333e+08 | C16: =$B$9 -> 16833333 | D16: =B16-C16 -> 4.695e+08
A17: =A16+Increment -> 5 | B17: =D16 -> 4.695e+08 | C17: =$B$9 -> 16833333 | D17: =B17-C17 -> 4.5266667e+08
A18: =A17+Increment -> 6 | B18: =D17 -> 4.5266667e+08 | C18: =$B$9 -> 16833333 | D18: =B18-C18 -> 4.3583333e+08
A19: =A18+Increment -> 7 | B19: =D18 -> 4.3583333e+08 | C19: =$B$9 -> 16833333 | D19: =B19-C19 -> 4.19e+08
A20: =A19+Increment -> 8 | B20: =D19 -> 4.19e+08 | C20: =$B$9 -> 16833333 | D20: =B20-C20 -> 4.0216667e+08
A21: =A20+Increment -> 9 | B21: =D20 -> 4.0216667e+08 | C21: =$B$9 -> 16833333 | D21: =B21-C21 -> 3.8533333e+08
A22: =A21+Increment -> 10 | B22: =D21 -> 3.8533333e+08 | C22: =$B$9 -> 16833333 | D22: =B22-C22 -> 3.685e+08
A23: =A22+Increment -> 11 | B23: =D22 -> 3.685e+08 | C23: =$B$9 -> 16833333 | D23: =B23-C23 -> 3.5166667e+08
A24: =A23+Increment -> 12 | B24: =D23 -> 3.5166667e+08 | C24: =$B$9 -> 16833333 | D24: =B24-C24 -> 3.3483333e+08
A25: =A24+Increment -> 13 | B25: =D24 -> 3.3483333e+08 | C25: =$B$9 -> 16833333 | D25: =B25-C25 -> 3.18e+08
A26: =A25+Increment -> 14 | B26: =D25 -> 3.18e+08 | C26: =$B$9 -> 16833333 | D26: =B26-C26 -> 3.0116667e+08
... A43: =A42+Increment -> 31 | B43: =D42 -> 31833333 | C43: =$B$9 -> 16833333 | D43: =B43-C43 -> 15000000
A46: NATURAL GAS (NG) REVENUE | F46: NATURAL GAS (NG) PURCHASE
A47: Year | B47: NG Sales Voulme ($) | C47: NG Selling Price ($/M3) | D47: NG Total Revenue ($) | F47: Year | G47: NG Purchase Voulme ($) | H47: NG Cost Price ($/M3) | I47: NG Total Cost ($)
A48: =Increment -> 1 | F48: =Increment -> 1
A49: =A48+Increment -> 2 | B49: {=Base_NG_Demand*(Increment+Demand_Increase)^(A49-First_Yr)} -> 17000000000 | C49: {=Sell_price_NG*(Inflation_Annual+Increment)^(A49-First_Yr)} -> 0.052 | D49: =B49*C49 -> 884000000 | F49: =F48+Increment -> 2 | G49: {=Base_NG_Demand*(Increment+Demand_Increase)^(A49-First_Yr)} -> 17000000000 | H49: {=Purch_price_NG*(Inflation_Annual+Increment)^(F49-First_Yr)} -> 0.046 | I49: =G49*H49 -> 782000000
A50: =A49+Increment -> 3 | B50: {=Base_NG_Demand*(Increment+Demand_Increase)^(A50-First_Yr)} -> 1.7085e+10 | C50: {=Sell_price_NG*(Inflation_Annual+Increment)^(A50-First_Yr)} -> 0.05278 | D50: =B50*C50 -> 9.017463e+08 | F50: =F49+Increment -> 3 | G50: {=Base_NG_Demand*(Increment+Demand_Increase)^(A50-First_Yr)} -> 1.7085e+10 | H50: {=Purch_price_NG*(Inflation_Annual+Increment)^(F50-First_Yr)} -> 0.04669 | I50: =G50*H50 -> 7.9769865e+08
A51: =A50+Increment -> 4 | B51: {=Base_NG_Demand*(Increment+Demand_Increase)^(A51-First_Yr)} -> 1.7170425e+10 | C51: {=Sell_price_NG*(Inflation_Annual+Increment)^(A51-First_Yr)} -> 0.0535717 | D51: =B51*C51 -> 9.1984886e+08 | F51: =F50+Increment -> 4 | G51: {=Base_NG_Demand*(Increment+Demand_Increase)^(A51-First_Yr)} -> 1.7170425e+10 | H51: {=Purch_price_NG*(Inflation_Annual+Increment)^(F51-First_Yr)} -> 0.04739035 | I51: =G51*H51 -> 8.1371245e+08
A52: =A51+Increment -> 5 | B52: {=Base_NG_Demand*(Increment+Demand_Increase)^(A52-First_Yr)} -> 1.7256277e+10 | C52: {=Sell_price_NG*(Inflation_Annual+Increment)^(A52-First_Yr)} -> 0.054375275 | D52: =B52*C52 -> 9.3831482e+08 | F52: =F51+Increment -> 5 | G52: {=Base_NG_Demand*(Increment+Demand_Increase)^(A52-First_Yr)} -> 1.7256277e+10 | H52: {=Purch_price_NG*(Inflation_Annual+Increment)^(F52-First_Yr)} -> 0.048101205 | I52: =G52*H52 -> 8.3004773e+08
A53: =A52+Increment -> 6 | B53: {=Base_NG_Demand*(Increment+Demand_Increase)^(A53-First_Yr)} -> 1.7342559e+10 | C53: {=Sell_price_NG*(Inflation_Annual+Increment)^(A53-First_Yr)} -> 0.055190905 | D53: =B53*C53 -> 9.5715149e+08 | F53: =F52+Increment -> 6 | G53: {=Base_NG_Demand*(Increment+Demand_Increase)^(A53-First_Yr)} -> 1.7342559e+10 | H53: {=Purch_price_NG*(Inflation_Annual+Increment)^(F53-First_Yr)} -> 0.048822723 | I53: =G53*H53 -> 8.4671094e+08
A54: =A53+Increment -> 7 | B54: {=Base_NG_Demand*(Increment+Demand_Increase)^(A54-First_Yr)} -> 1.7429271e+10 | C54: {=Sell_price_NG*(Inflation_Annual+Increment)^(A54-First_Yr)} -> 0.056018768 | D54: =B54*C54 -> 9.7636631e+08 | F54: =F53+Increment -> 7 | G54: {=Base_NG_Demand*(Increment+Demand_Increase)^(A54-First_Yr)} -> 1.7429271e+10 | H54: {=Purch_price_NG*(Inflation_Annual+Increment)^(F54-First_Yr)} -> 0.049555064 | I54: =G54*H54 -> 8.6370866e+08
A55: =A54+Increment -> 8 | B55: {=Base_NG_Demand*(Increment+Demand_Increase)^(A55-First_Yr)} -> 1.7516418e+10 | C55: {=Sell_price_NG*(Inflation_Annual+Increment)^(A55-First_Yr)} -> 0.05685905 | D55: =B55*C55 -> 9.9596686e+08 | F55: =F54+Increment -> 8 | G55: {=Base_NG_Demand*(Increment+Demand_Increase)^(A55-First_Yr)} -> 1.7516418e+10 | H55: {=Purch_price_NG*(Inflation_Annual+Increment)^(F55-First_Yr)} -> 0.05029839 | I55: =G55*H55 -> 8.8104761e+08
A56: =A55+Increment -> 9 | B56: {=Base_NG_Demand*(Increment+Demand_Increase)^(A56-First_Yr)} -> 1.7604e+10 | C56: {=Sell_price_NG*(Inflation_Annual+Increment)^(A56-First_Yr)} -> 0.057711935 | D56: =B56*C56 -> 1.0159609e+09 | F56: =F55+Increment -> 9 | G56: {=Base_NG_Demand*(Increment+Demand_Increase)^(A56-First_Yr)} -> 1.7604e+10 | H56: {=Purch_price_NG*(Inflation_Annual+Increment)^(F56-First_Yr)} -> 0.051052866 | I56: =G56*H56 -> 8.9873464e+08
A57: =A56+Increment -> 10 | B57: {=Base_NG_Demand*(Increment+Demand_Increase)^(A57-First_Yr)} -> 1.769202e+10 | C57: {=Sell_price_NG*(Inflation_Annual+Increment)^(A57-First_Yr)} -> 0.058577615 | D57: =B57*C57 -> 1.0363563e+09 | F57: =F56+Increment -> 10 | G57: {=Base_NG_Demand*(Increment+Demand_Increase)^(A57-First_Yr)} -> 1.769202e+10 | H57: {=Purch_price_NG*(Inflation_Annual+Increment)^(F57-First_Yr)} -> 0.051818659 | I57: =G57*H57 -> 9.1677674e+08
A58: =A57+Increment -> 11 | B58: {=Base_NG_Demand*(Increment+Demand_Increase)^(A58-First_Yr)} -> 1.778048e+10 | C58: {=Sell_price_NG*(Inflation_Annual+Increment)^(A58-First_Yr)} -> 0.059456279 | D58: =B58*C58 -> 1.0571612e+09 | F58: =F57+Increment -> 11 | G58: {=Base_NG_Demand*(Increment+Demand_Increase)^(A58-First_Yr)} -> 1.778048e+10 | H58: {=Purch_price_NG*(Inflation_Annual+Increment)^(F58-First_Yr)} -> 0.052595939 | I58: =G58*H58 -> 9.3518103e+08
A59: =A58+Increment -> 12 | B59: {=Base_NG_Demand*(Increment+Demand_Increase)^(A59-First_Yr)} -> 1.7869382e+10 | C59: {=Sell_price_NG*(Inflation_Annual+Increment)^(A59-First_Yr)} -> 0.060348123 | D59: =B59*C59 -> 1.0783837e+09 | F59: =F58+Increment -> 12 | G59: {=Base_NG_Demand*(Increment+Demand_Increase)^(A59-First_Yr)} -> 1.7869382e+10 | H59: {=Purch_price_NG*(Inflation_Annual+Increment)^(F59-First_Yr)} -> 0.053384878 | I59: =G59*H59 -> 9.5395479e+08
A60: =A59+Increment -> 13 | B60: {=Base_NG_Demand*(Increment+Demand_Increase)^(A60-First_Yr)} -> 1.7958729e+10 | C60: {=Sell_price_NG*(Inflation_Annual+Increment)^(A60-First_Yr)} -> 0.061253345 | D60: =B60*C60 -> 1.1000322e+09 | F60: =F59+Increment -> 13 | G60: {=Base_NG_Demand*(Increment+Demand_Increase)^(A60-First_Yr)} -> 1.7958729e+10 | H60: {=Purch_price_NG*(Inflation_Annual+Increment)^(F60-First_Yr)} -> 0.054185651 | I60: =G60*H60 -> 9.7310543e+08
...

Sheet Tanker Schedule
A1: QATAR ENERGY
A2: TANKER SCHEDULE
A4: CAPITAL ASSETS
B5: Tanker
A6: Capital Assets | B6: =Building_Cost_Tanker -> 250000000
A7: Useful Life | B7: =Useful_Life -> 30
A8: Salvage value | B8: =Salvage_Val_Tanker -> 20000000
A9: Annual Depreciation | B9: =(Building_Cost_Tanker-Salvage_Val_Tanker)/Useful_Life -> 7666666.7
A11: DEPRECIATION SCHEDULE
A12: Year | B12: Begininng Value | C12: Depreciation Amount | D12: Remaining Amount
A13: =Increment -> 1
A14: =A13+Increment -> 2 | B14: =B6 -> 250000000 | C14: =$B$9 -> 7666666.7 | D14: =B14-C14 -> 2.4233333e+08
A15: =A14+Increment -> 3 | B15: =D14 -> 2.4233333e+08 | C15: =$B$9 -> 7666666.7 | D15: =B15-C15 -> 2.3466667e+08
A16: =A15+Increment -> 4 | B16: =D15 -> 2.3466667e+08 | C16: =$B$9 -> 7666666.7 | D16: =B16-C16 -> 2.27e+08
A17: =A16+Increment -> 5 | B17: =D16 -> 2.27e+08 | C17: =$B$9 -> 7666666.7 | D17: =B17-C17 -> 2.1933333e+08
A18: =A17+Increment -> 6 | B18: =D17 -> 2.1933333e+08 | C18: =$B$9 -> 7666666.7 | D18: =B18-C18 -> 2.1166667e+08
A19: =A18+Increment -> 7 | B19: =D18 -> 2.1166667e+08 | C19: =$B$9 -> 7666666.7 | D19: =B19-C19 -> 2.04e+08
A20: =A19+Increment -> 8 | B20: =D19 -> 2.04e+08 | C20: =$B$9 -> 7666666.7 | D20: =B20-C20 -> 1.9633333e+08
A21: =A20+Increment -> 9 | B21: =D20 -> 1.9633333e+08 | C21: =$B$9 -> 7666666.7 | D21: =B21-C21 -> 1.8866667e+08
A22: =A21+Increment -> 10 | B22: =D21 -> 1.8866667e+08 | C22: =$B$9 -> 7666666.7 | D22: =B22-C22 -> 1.81e+08
A23: =A22+Increment -> 11 | B23: =D22 -> 1.81e+08 | C23: =$B$9 -> 7666666.7 | D23: =B23-C23 -> 1.7333333e+08
A24: =A23+Increment -> 12 | B24: =D23 -> 1.7333333e+08 | C24: =$B$9 -> 7666666.7 | D24: =B24-C24 -> 1.6566667e+08
A25: =A24+Increment -> 13 | B25: =D24 -> 1.6566667e+08 | C25: =$B$9 -> 7666666.7 | D25: =B25-C25 -> 1.58e+08
A26: =A25+Increment -> 14 | B26: =D25 -> 1.58e+08 | C26: =$B$9 -> 7666666.7 | D26: =B26-C26 -> 1.5033333e+08
... A43: =A42+Increment -> 31 | B43: =D42 -> 27666667 | C43: =$B$9 -> 7666666.7 | D43: =B43-C43 -> 20000000
A45: EMPLOYMENT COST SCHEDULE
A46: Year | B46: Total Salary Cost | C46: Base Salary | D46: Employer Social Insurance | E46: Employee Deduction | F46: Payment to Employees | G46: Remittance to Government | H46: Monthly Payment to Employees | I46: Monthly Remittance to Government
A47: =Increment -> 1
A48: =A47+Increment -> 2 | B48: =Total_Crew_Costs -> 3500000 | C48: {=B48/(Increment+Employer_Social_Insurance_Rate)} -> 3070175.4 | D48: {=C48*Employer_Social_Insurance_Rate} -> 429824.56 | E48: {=C48*Employee_Deduction_Rate} -> 214912.28 | F48: =C48-E48 -> 2855263.2 | G48: =E48+D48 -> 644736.84 | H48: =F48/M_i_Y -> 237938.6 | I48: =G48/M_i_Y -> 53728.07
A49: =A48+Increment -> 3 | B49: =B48*(Increment+Inflation_Annual) -> 3552500 | C49: {=B49/(Increment+Employer_Social_Insurance_Rate)} -> 3116228.1 | D49: {=C49*Employer_Social_Insurance_Rate} -> 436271.93 | E49: {=C49*Employee_Deduction_Rate} -> 218135.96 | F49: =C49-E49 -> 2898092.1 | G49: =E49+D49 -> 654407.89 | H49: =F49/M_i_Y -> 241507.68 | I49: =G49/M_i_Y -> 54533.991
A50: =A49+Increment -> 4 | B50: =B49*(Increment+Inflation_Annual) -> 3605787.5 | C50: {=B50/(Increment+Employer_Social_Insurance_Rate)} -> 3162971.5 | D50: {=C50*Employer_Social_Insurance_Rate} -> 442816.01 | E50: {=C50*Employee_Deduction_Rate} -> 221408 | F50: =C50-E50 -> 2941563.5 | G50: =E50+D50 -> 664224.01 | H50: =F50/M_i_Y -> 245130.29 | I50: =G50/M_i_Y -> 55352.001
A51: =A50+Increment -> 5 | B51: =B50*(Increment+Inflation_Annual) -> 3659874.3 | C51: {=B51/(Increment+Employer_Social_Insurance_Rate)} -> 3210416.1 | D51: {=C51*Employer_Social_Insurance_Rate} -> 449458.25 | E51: {=C51*Employee_Deduction_Rate} -> 224729.12 | F51: =C51-E51 -> 2985686.9 | G51: =E51+D51 -> 674187.37 | H51: =F51/M_i_Y -> 248807.24 | I51: =G51/M_i_Y -> 56182.281
A52: =A51+Increment -> 6 | B52: =B51*(Increment+Inflation_Annual) -> 3714772.4 | C52: {=B52/(Increment+Employer_Social_Insurance_Rate)} -> 3258572.3 | D52: {=C52*Employer_Social_Insurance_Rate} -> 456200.12 | E52: {=C52*Employee_Deduction_Rate} -> 228100.06 | F52: =C52-E52 -> 3030472.2 | G52: =E52+D52 -> 684300.18 | H52: =F52/M_i_Y -> 252539.35 | I52: =G52/M_i_Y -> 57025.015
A53: =A52+Increment -> 7 | B53: =B52*(Increment+Inflation_Annual) -> 3770494 | C53: {=B53/(Increment+Employer_Social_Insurance_Rate)} -> 3307450.9 | D53: {=C53*Employer_Social_Insurance_Rate} -> 463043.12 | E53: {=C53*Employee_Deduction_Rate} -> 231521.56 | F53: =C53-E53 -> 3075929.3 | G53: =E53+D53 -> 694564.69 | H53: =F53/M_i_Y -> 256327.44 | I53: =G53/M_i_Y -> 57880.391
A54: =A53+Increment -> 8 | B54: =B53*(Increment+Inflation_Annual) -> 3827051.4 | C54: {=B54/(Increment+Employer_Social_Insurance_Rate)} -> 3357062.7 | D54: {=C54*Employer_Social_Insurance_Rate} -> 469988.77 | E54: {=C54*Employee_Deduction_Rate} -> 234994.39 | F54: =C54-E54 -> 3122068.3 | G54: =E54+D54 -> 704983.16 | H54: =F54/M_i_Y -> 260172.36 | I54: =G54/M_i_Y -> 58748.596
A55: =A54+Increment -> 9 | B55: =B54*(Increment+Inflation_Annual) -> 3884457.2 | C55: {=B55/(Increment+Employer_Social_Insurance_Rate)} -> 3407418.6 | D55: {=C55*Employer_Social_Insurance_Rate} -> 477038.6 | E55: {=C55*Employee_Deduction_Rate} -> 238519.3 | F55: =C55-E55 -> 3168899.3 | G55: =E55+D55 -> 715557.9 | H55: =F55/M_i_Y -> 264074.94 | I55: =G55/M_i_Y -> 59629.825
A56: =A55+Increment -> 10 | B56: =B55*(Increment+Inflation_Annual) -> 3942724.1 | C56: {=B56/(Increment+Employer_Social_Insurance_Rate)} -> 3458529.9 | D56: {=C56*Employer_Social_Insurance_Rate} -> 484194.18 | E56: {=C56*Employee_Deduction_Rate} -> 242097.09 | F56: =C56-E56 -> 3216432.8 | G56: =E56+D56 -> 726291.27 | H56: =F56/M_i_Y -> 268036.07 | I56: =G56/M_i_Y -> 60524.273
A57: =A56+Increment -> 11 | B57: =B56*(Increment+Inflation_Annual) -> 4001864.9 | C57: {=B57/(Increment+Employer_Social_Insurance_Rate)} -> 3510407.8 | D57: {=C57*Employer_Social_Insurance_Rate} -> 491457.09 | E57: {=C57*Employee_Deduction_Rate} -> 245728.55 | F57: =C57-E57 -> 3264679.3 | G57: =E57+D57 -> 737185.64 | H57: =F57/M_i_Y -> 272056.61 | I57: =G57/M_i_Y -> 61432.137
A58: =A57+Increment -> 12 | B58: =B57*(Increment+Inflation_Annual) -> 4061892.9 | C58: {=B58/(Increment+Employer_Social_Insurance_Rate)} -> 3563063.9 | D58: {=C58*Employer_Social_Insurance_Rate} -> 498828.95 | E58: {=C58*Employee_Deduction_Rate} -> 249414.48 | F58: =C58-E58 -> 3313649.5 | G58: =E58+D58 -> 748243.43 | H58: =F58/M_i_Y -> 276137.46 | I58: =G58/M_i_Y -> 62353.619
A59: =A58+Increment -> 13 | B59: =B58*(Increment+Inflation_Annual) -> 4122821.3 | C59: {=B59/(Increment+Employer_Social_Insurance_Rate)} -> 3616509.9 | D59: {=C59*Employer_Social_Insurance_Rate} -> 506311.39 | E59: {=C59*Employee_Deduction_Rate} -> 253155.69 | F59: =C59-E59 -> 3363354.2 | G59: =E59+D59 -> 759467.08 | H59: =F59/M_i_Y -> 280279.52 | I59: =G59/M_i_Y -> 63288.923
...

Sheet Cash Budget
A1: QATAR ENERGY
A2: CASH BUDGET
A3: FOR THE FINANCIAL YEARS ENDED DECEMBER 31
B5: Year 1 | N5: Year 1 Total | O5: Year 2 | AA5: Year 2 Total | AB5: Year 3 | AC5: Year 4 | AD5: Year 5
B6: January | C6: February | D6: March | E6: April | F6: May | G6: June | H6: July | I6: August | J6: September | K6: October | L6: November | M6: December | O6: January | P6: February | Q6: March | R6: April | S6: May | T6: June | U6: July | V6: August | W6: September | X6: October | Y6: November | Z6: December
A7: Opening Cash | B7: {=Nil} -> 0 | C7: =B33 -> 833333.33 | D7: =C33 -> 1666666.7 | E7: =D33 -> 2500000 | F7: =E33 -> 3333333.3 | G7: =F33 -> 4166666.7 | H7: =G33 -> 5000000 | I7: =H33 -> 5833333.3 | J7: =I33 -> 6666666.7 | ... M7: =L33 -> 9166666.7 | N7: =B7 -> 0 | O7: =M33 -> 10000000 | P7: =O33 -> 70031911 | Q7: =P33 -> 72666805 | R7: =Q33 -> 85966655 | S7: =R33 -> 92402152 | T7: =S33 -> 1.0271581e+08 | U7: =T33 -> 1.0915131e+08 | V7: =U33 -> 1.1946497e+08 | W7: =V33 -> 1.2807224e+08 | ... Z7: =Y33 -> 1.512569e+08 | AA7: =O7 -> 10000000 | AB7: =Z33 -> 1.4619836e+08 | AC7: =AB33 -> 2.3102332e+08 | AD7: =AC33 -> 3.1764408e+08
A8: Bank Loan Drawn-out | B8: ='Tanker Schedule'!$J$201 -> 21666667 | C8: ='Tanker Schedule'!$J$201 -> 21666667 | D8: ='Tanker Schedule'!$J$201 -> 21666667 | E8: ='Tanker Schedule'!$J$201 -> 21666667 | F8: ='Tanker Schedule'!$J$201 -> 21666667 | G8: ='Tanker Schedule'!$J$201 -> 21666667 | H8: ='Tanker Schedule'!$J$201 -> 21666667 | I8: ='Tanker Schedule'!$J$201 -> 21666667 | ... M8: ='Tanker Schedule'!$J$201 -> 21666667 | N8: =SUM(B8:M8) -> 2.6e+08 | O8: {=Nil} -> 0 | P8: {=Nil} -> 0 | Q8: {=Nil} -> 0 | R8: {=Nil} -> 0 | S8: {=Nil} -> 0 | T8: {=Nil} -> 0 | U8: {=Nil} -> 0 | V8: {=Nil} -> 0 | ... Z8: {=Nil} -> 0 | AA8: =SUM(O8:Z8) -> 0 | AB8: {=Nil} -> 0 | AC8: {=Nil} -> 0 | AD8: {=Nil} -> 0
A9: Revenue | B9: {=Nil} -> 0 | C9: {=Nil} -> 0 | D9: {=Nil} -> 0 | E9: {=Nil} -> 0 | F9: {=Nil} -> 0 | G9: {=Nil} -> 0 | H9: {=Nil} -> 0 | I9: {=Nil} -> 0 | ... M9: {=Nil} -> 0 | N9: =SUM(B9:M9) -> 0 | O9: {='Tanker Schedule'!D82/D_i_Y*(Days_Jan-Increment)} -> 65153183 | P9: {='Tanker Schedule'!D82/D_i_Y*Days_Feb} -> 61352580 | Q9: {='Tanker Schedule'!D82/D_i_Y*Days_Mar} -> 67324956 | R9: {='Tanker Schedule'!D82/D_i_Y*Days_Apr} -> 65153183 | S9: {='Tanker Schedule'!D82/D_i_Y*Days_May} -> 67324956 | T9: {='Tanker Schedule'!D82/D_i_Y*Days_Jun} -> 65153183 | U9: {='Tanker Schedule'!D82/D_i_Y*Days_Jul} -> 67324956 | V9: {='Tanker Schedule'!D82/D_i_Y*Days_Aug} -> 67324956 | W9: {='Tanker Schedule'!D82/D_i_Y*Days_Sept} -> 65153183 | X9: {='Tanker Schedule'!D82/D_i_Y*Days_Oct} -> 67324956 | Y9: {='Tanker Schedule'!D82/D_i_Y*Days_Nov} -> 65153183 | Z9: {='Tanker Schedule'!D82/D_i_Y*Days_Dec} -> 67324956 | AA9: =SUM(O9:Z9) -> 7.9106823e+08 | AB9: =('Tanker Schedule'!D82/D_i_Y)+('Tanker Schedule'!D83)-('Tanker Schedule'!D83/D_i_Y) -> 8.0912069e+08 | AC9: =('Tanker Schedule'!D83/D_i_Y)+('Tanker Schedule'!D84)-('Tanker Schedule'!D84/D_i_Y) -> 8.2536379e+08 | AD9: =('Tanker Schedule'!D84/D_i_Y)+('Tanker Schedule'!D85)-('Tanker Schedule'!D85/D_i_Y) -> 8.4193297e+08
A10: Total Cash Inflows: | B10: =SUM(B8:B9) -> 21666667 | C10: =SUM(C8:C9) -> 21666667 | D10: =SUM(D8:D9) -> 21666667 | E10: =SUM(E8:E9) -> 21666667 | F10: =SUM(F8:F9) -> 21666667 | G10: =SUM(G8:G9) -> 21666667 | H10: =SUM(H8:H9) -> 21666667 | I10: =SUM(I8:I9) -> 21666667 | ... M10: =SUM(M8:M9) -> 21666667 | N10: =SUM(B10:M10) -> 2.6e+08 | O10: =SUM(O8:O9) -> 65153183 | P10: =SUM(P8:P9) -> 61352580 | Q10: =SUM(Q8:Q9) -> 67324956 | R10: =SUM(R8:R9) -> 65153183 | S10: =SUM(S8:S9) -> 67324956 | T10: =SUM(T8:T9) -> 65153183 | U10: =SUM(U8:U9) -> 67324956 | V10: =SUM(V8:V9) -> 67324956 | ... AD10: =SUM(AD8:AD9) -> 8.4193297e+08
A12: Initial Capital Expenditures:
A13: Tanker Building Cost | B13: =Building_Cost_Tanker/M_i_Y -> 20833333 | C13: =Building_Cost_Tanker/M_i_Y -> 20833333 | D13: =Building_Cost_Tanker/M_i_Y -> 20833333 | E13: =Building_Cost_Tanker/M_i_Y -> 20833333 | F13: =Building_Cost_Tanker/M_i_Y -> 20833333 | G13: =Building_Cost_Tanker/M_i_Y -> 20833333 | H13: =Building_Cost_Tanker/M_i_Y -> 20833333 | I13: =Building_Cost_Tanker/M_i_Y -> 20833333 | ... M13: =Building_Cost_Tanker/M_i_Y -> 20833333 | N13: =SUM(B13:M13) -> 2.5e+08 | O13: {=Nil} -> 0 | P13: {=Nil} -> 0 | Q13: {=Nil} -> 0 | R13: {=Nil} -> 0 | S13: {=Nil} -> 0 | T13: {=Nil} -> 0 | U13: {=Nil} -> 0 | V13: {=Nil} -> 0 | ... Z13: {=Nil} -> 0 | AA13: =SUM(O13:Z13) -> 0 | AB13: {=Nil} -> 0 | AC13: {=Nil} -> 0 | AD13: {=Nil} -> 0
A14: Trip Costs: | AA14: =SUM(O14:Z14) -> 0
A15: Port fees | B15: {=Nil} -> 0 | C15: {=Nil} -> 0 | D15: {=Nil} -> 0 | E15: {=Nil} -> 0 | F15: {=Nil} -> 0 | G15: {=Nil} -> 0 | H15: {=Nil} -> 0 | I15: {=Nil} -> 0 | ... M15: {=Nil} -> 0 | N15: =SUM(B15:M15) -> 0 | O15: {=Nil} -> 0 | P15: ='Tanker Schedule'!$D$116/M_i_Y -> 1998333.3 | Q15: ='Tanker Schedule'!$D$116/M_i_Y -> 1998333.3 | R15: ='Tanker Schedule'!$D$116/M_i_Y -> 1998333.3 | S15: ='Tanker Schedule'!$D$116/M_i_Y -> 1998333.3 | T15: ='Tanker Schedule'!$D$116/M_i_Y -> 1998333.3 | U15: ='Tanker Schedule'!$D$116/M_i_Y -> 1998333.3 | V15: ='Tanker Schedule'!$D$116/M_i_Y -> 1998333.3 | W15: ='Tanker Schedule'!$D$116/M_i_Y -> 1998333.3 | ... Z15: ='Tanker Schedule'!$D$116/M_i_Y -> 1998333.3 | AA15: =SUM(O15:Z15) -> 21981667 | AB15: =('Tanker Schedule'!D116/M_i_Y)+('Tanker Schedule'!D117*(M_i_Y-Increment)/M_i_Y) -> 24514417 | AC15: =('Tanker Schedule'!D117/M_i_Y)+('Tanker Schedule'!D118*(M_i_Y-Increment)/M_i_Y) -> 25108503 | AD15: =('Tanker Schedule'!D118/M_i_Y)+('Tanker Schedule'!D119*(M_i_Y-Increment)/M_i_Y) -> 25504018
A16: Heavy Fuel Oil | B16: {=Nil} -> 0 | C16: {=Nil} -> 0 | D16: {=Nil} -> 0 | E16: {=Nil} -> 0 | F16: {=Nil} -> 0 | G16: {=Nil} -> 0 | H16: {=Nil} -> 0 | I16: {=Nil} -> 0 | ... M16: {=Nil} -> 0 | N16: =SUM(B16:M16) -> 0 | O16: {=Nil} -> 0 | P16: ='Tanker Schedule'!$I$116/M_i_Y -> 82840 | Q16: ='Tanker Schedule'!$I$116/M_i_Y -> 82840 | R16: ='Tanker Schedule'!$I$116/M_i_Y -> 82840 | S16: ='Tanker Schedule'!$I$116/M_i_Y -> 82840 | T16: ='Tanker Schedule'!$I$116/M_i_Y -> 82840 | U16: ='Tanker Schedule'!$I$116/M_i_Y -> 82840 | V16: ='Tanker Schedule'!$I$116/M_i_Y -> 82840 | W16: ='Tanker Schedule'!$I$116/M_i_Y -> 82840 | ... Z16: ='Tanker Schedule'!$I$116/M_i_Y -> 82840 | AA16: =SUM(O16:Z16) -> 911240 | AB16: =('Tanker Schedule'!I116/M_i_Y)+('Tanker Schedule'!I117*(M_i_Y-Increment)/M_i_Y) -> 1016234 | AC16: =('Tanker Schedule'!I117/M_i_Y)+('Tanker Schedule'!I118*(M_i_Y-Increment)/M_i_Y) -> 1040861.6 | AD16: =('Tanker Schedule'!I118/M_i_Y)+('Tanker Schedule'!I119*(M_i_Y-Increment)/M_i_Y) -> 1057257.5
A17: Shipping Operating Expense | B17: {=Nil} -> 0 | C17: {=Nil} -> 0 | D17: {=Nil} -> 0 | E17: {=Nil} -> 0 | F17: {=Nil} -> 0 | G17: {=Nil} -> 0 | H17: {=Nil} -> 0 | I17: {=Nil} -> 0 | ... M17: {=Nil} -> 0 | N17: =SUM(B17:M17) -> 0 | O17: {=Nil} -> 0 | P17: ='Tanker Schedule'!$D$150/M_i_Y -> 363333.33 | Q17: ='Tanker Schedule'!$D$150/M_i_Y -> 363333.33 | R17: ='Tanker Schedule'!$D$150/M_i_Y -> 363333.33 | S17: ='Tanker Schedule'!$D$150/M_i_Y -> 363333.33 | T17: ='Tanker Schedule'!$D$150/M_i_Y -> 363333.33 | U17: ='Tanker Schedule'!$D$150/M_i_Y -> 363333.33 | V17: ='Tanker Schedule'!$D$150/M_i_Y -> 363333.33 | W17: ='Tanker Schedule'!$D$150/M_i_Y -> 363333.33 | ... Z17: ='Tanker Schedule'!$D$150/M_i_Y -> 363333.33 | AA17: =SUM(O17:Z17) -> 3996666.7 | AB17: =('Tanker Schedule'!D150/M_i_Y)+('Tanker Schedule'!D151*(M_i_Y-Increment)/M_i_Y) -> 4457166.7 | AC17: =('Tanker Schedule'!D151/M_i_Y)+('Tanker Schedule'!D152*(M_i_Y-Increment)/M_i_Y) -> 4565182.4 | AD17: =('Tanker Schedule'!D152/M_i_Y)+('Tanker Schedule'!D153*(M_i_Y-Increment)/M_i_Y) -> 4637094.2
A18: LNG Purchase | B18: {=Nil} -> 0 | C18: {=Nil} -> 0 | D18: {=Nil} -> 0 | E18: {=Nil} -> 0 | F18: {=Nil} -> 0 | G18: {=Nil} -> 0 | H18: {=Nil} -> 0 | I18: {=Nil} -> 0 | ... M18: {=Nil} -> 0 | N18: =SUM(B18:M18) -> 0 | O18: {=Nil} -> 0 | P18: {='Tanker Schedule'!$I$82/D_i_Y*Days_Jan} -> 52898179 | Q18: {='Tanker Schedule'!$I$82/D_i_Y*Days_Feb} -> 48205599 | R18: {='Tanker Schedule'!$I$82/D_i_Y*Days_Mar} -> 52898179 | S18: {='Tanker Schedule'!$I$82/D_i_Y*Days_Apr} -> 51191786 | T18: {='Tanker Schedule'!$I$82/D_i_Y*Days_May} -> 52898179 | U18: {='Tanker Schedule'!$I$82/D_i_Y*Days_Jun} -> 51191786 | V18: {='Tanker Schedule'!$I$82/D_i_Y*Days_Jul} -> 52898179 | W18: {='Tanker Schedule'!$I$82/D_i_Y*Days_Aug} -> 52898179 | X18: {='Tanker Schedule'!$I$82/D_i_Y*Days_Sept} -> 51191786 | Y18: {='Tanker Schedule'!$I$82/D_i_Y*Days_Oct} -> 52898179 | Z18: {='Tanker Schedule'!$I$82/D_i_Y*Days_Nov} -> 51191786 | AA18: =SUM(O18:Z18) -> 5.7036182e+08 | AB18: {=('Tanker Schedule'!$I$82/D_i_Y*Days_Dec)+('Tanker Schedule'!I83*(D_i_Y-Days_Dec)/D_i_Y)} -> 6.3471001e+08 | AC18: {=('Tanker Schedule'!I83/D_i_Y*Days_Dec)+('Tanker Schedule'!I84*(D_i_Y-Days_Dec)/D_i_Y)} -> 6.4745182e+08 | AD18: {=('Tanker Schedule'!I84/D_i_Y*Days_Dec)+('Tanker Schedule'!I85*(D_i_Y-Days_Dec)/D_i_Y)} -> 6.6044941e+08
A19: Operating Costs:
A20: Insurance | B20: {=Nil} -> 0 | C20: {=Nil} -> 0 | D20: {=Nil} -> 0 | E20: {=Nil} -> 0 | F20: {=Nil} -> 0 | G20: {=Nil} -> 0 | H20: {=Nil} -> 0 | I20: {=Nil} -> 0 | ... M20: {=Nil} -> 0 | N20: =SUM(B20:M20) -> 0 | O20: =Insurance_Tanker -> 1800000 | P20: {=Nil} -> 0 | Q20: {=Nil} -> 0 | R20: {=Nil} -> 0 | S20: {=Nil} -> 0 | T20: {=Nil} -> 0 | U20: {=Nil} -> 0 | V20: {=Nil} -> 0 | W20: {=Nil} -> 0 | ... Z20: {=Nil} -> 0 | AA20: =SUM(O20:Z20) -> 1800000 | AB20: =AA20*(Increment+Inflation_Annual) -> 1827000 | AC20: =AB20*(Increment+Inflation_Annual) -> 1854405 | AD20: =AC20*(Increment+Inflation_Annual) -> 1882221.1
A21: Payroll - Payment to Employees | B21: {=Nil} -> 0 | C21: {=Nil} -> 0 | D21: {=Nil} -> 0 | E21: {=Nil} -> 0 | F21: {=Nil} -> 0 | G21: {=Nil} -> 0 | H21: {=Nil} -> 0 | I21: {=Nil} -> 0 | ... M21: {=Nil} -> 0 | N21: =SUM(B21:M21) -> 0 | O21: ='Tanker Schedule'!$H$48 -> 237938.6 | P21: ='Tanker Schedule'!$H$48 -> 237938.6 | Q21: ='Tanker Schedule'!$H$48 -> 237938.6 | R21: ='Tanker Schedule'!$H$48 -> 237938.6 | S21: ='Tanker Schedule'!$H$48 -> 237938.6 | T21: ='Tanker Schedule'!$H$48 -> 237938.6 | U21: ='Tanker Schedule'!$H$48 -> 237938.6 | V21: ='Tanker Schedule'!$H$48 -> 237938.6 | ... Z21: ='Tanker Schedule'!$H$48 -> 237938.6 | AA21: =SUM(O21:Z21) -> 2855263.2 | AB21: ='Tanker Schedule'!F49 -> 2898092.1 | AC21: ='Tanker Schedule'!F50 -> 2941563.5 | AD21: ='Tanker Schedule'!F51 -> 2985686.9
A22: Payroll - Remittance to Government | O22: {=Nil} -> 0 | P22: ='Tanker Schedule'!$I$48 -> 53728.07 | Q22: ='Tanker Schedule'!$I$48 -> 53728.07 | R22: ='Tanker Schedule'!$I$48 -> 53728.07 | S22: ='Tanker Schedule'!$I$48 -> 53728.07 | T22: ='Tanker Schedule'!$I$48 -> 53728.07 | U22: ='Tanker Schedule'!$I$48 -> 53728.07 | V22: ='Tanker Schedule'!$I$48 -> 53728.07 | W22: ='Tanker Schedule'!$I$48 -> 53728.07 | ... Z22: ='Tanker Schedule'!$I$48 -> 53728.07 | AA22: =SUM(O22:Z22) -> 591008.77 | AB22: ='Tanker Schedule'!I48+('Tanker Schedule'!I49*(M_i_Y-Increment)) -> 653601.97 | AC22: ='Tanker Schedule'!I49+('Tanker Schedule'!I50*(M_i_Y-Increment)) -> 663406 | AD22: ='Tanker Schedule'!I50+('Tanker Schedule'!I51*(M_i_Y-Increment)) -> 673357.09
A23: Maintenance and Engineering | B23: {=Nil} -> 0 | C23: {=Nil} -> 0 | D23: {=Nil} -> 0 | E23: {=Nil} -> 0 | F23: {=Nil} -> 0 | G23: {=Nil} -> 0 | H23: {=Nil} -> 0 | I23: {=Nil} -> 0 | ... M23: {=Nil} -> 0 | N23: =SUM(B23:M23) -> 0 | O23: =General_Tanker/M_i_Y -> 166666.67 | P23: =General_Tanker/M_i_Y -> 166666.67 | Q23: =General_Tanker/M_i_Y -> 166666.67 | R23: =General_Tanker/M_i_Y -> 166666.67 | S23: =General_Tanker/M_i_Y -> 166666.67 | T23: =General_Tanker/M_i_Y -> 166666.67 | U23: =General_Tanker/M_i_Y -> 166666.67 | V23: =General_Tanker/M_i_Y -> 166666.67 | ... Z23: =General_Tanker/M_i_Y -> 166666.67 | AA23: =SUM(O23:Z23) -> 2000000 | AB23: =AA23*(Increment+Inflation_Annual) -> 2030000 | AC23: =AB23*(Increment+Inflation_Annual) -> 2060450 | AD23: =AC23*(Increment+Inflation_Annual) -> 2091356.7
A24: Stores, spares, lubricants | B24: {=Nil} -> 0 | C24: {=Nil} -> 0 | D24: {=Nil} -> 0 | E24: {=Nil} -> 0 | F24: {=Nil} -> 0 | G24: {=Nil} -> 0 | H24: {=Nil} -> 0 | I24: {=Nil} -> 0 | ... M24: {=Nil} -> 0 | N24: =SUM(B24:M24) -> 0 | O24: =Stores_Spares_Lube/M_i_Y -> 166666.67 | P24: =Stores_Spares_Lube/M_i_Y -> 166666.67 | Q24: =Stores_Spares_Lube/M_i_Y -> 166666.67 | R24: =Stores_Spares_Lube/M_i_Y -> 166666.67 | S24: =Stores_Spares_Lube/M_i_Y -> 166666.67 | T24: =Stores_Spares_Lube/M_i_Y -> 166666.67 | U24: =Stores_Spares_Lube/M_i_Y -> 166666.67 | V24: =Stores_Spares_Lube/M_i_Y -> 166666.67 | ... Z24: =Stores_Spares_Lube/M_i_Y -> 166666.67 | AA24: =SUM(O24:Z24) -> 2000000 | AB24: =AA24*(Increment+Inflation_Annual) -> 2030000 | AC24: =AB24*(Increment+Inflation_Annual) -> 2060450 | AD24: =AC24*(Increment+Inflation_Annual) -> 2091356.7
A25: Carbon Offsets | B25: {=Nil} -> 0 | C25: {=Nil} -> 0 | D25: {=Nil} -> 0 | E25: {=Nil} -> 0 | F25: {=Nil} -> 0 | G25: {=Nil} -> 0 | H25: {=Nil} -> 0 | I25: {=Nil} -> 0 | ... M25: {=Nil} -> 0 | N25: =SUM(B25:M25) -> 0 | O25: =Carbon_Offset_Tanker/M_i_Y -> 2750000 | P25: =Carbon_Offset_Tanker/M_i_Y -> 2750000 | Q25: =Carbon_Offset_Tanker/M_i_Y -> 2750000 | R25: =Carbon_Offset_Tanker/M_i_Y -> 2750000 | S25: =Carbon_Offset_Tanker/M_i_Y -> 2750000 | T25: =Carbon_Offset_Tanker/M_i_Y -> 2750000 | U25: =Carbon_Offset_Tanker/M_i_Y -> 2750000 | V25: =Carbon_Offset_Tanker/M_i_Y -> 2750000 | ... Z25: =Carbon_Offset_Tanker/M_i_Y -> 2750000 | AA25: =SUM(O25:Z25) -> 33000000 | AB25: =AA25*(Increment+Inflation_Carbon_Offset) -> 34287000 | AC25: =AB25*(Increment+Inflation_Carbon_Offset) -> 35624193 | AD25: {=AC25*(Increment+Inflation_Carbon_Offset)*Y5_Carbon_Increase} -> 74027073
A26: Special Event Costs: | AA26: =SUM(O26:Z26) -> 0
A27: Port Damage (Insurance Payout 10%) | B27: {=Nil} -> 0 | C27: {=Nil} -> 0 | D27: {=Nil} -> 0 | E27: {=Nil} -> 0 | F27: {=Nil} -> 0 | G27: {=Nil} -> 0 | H27: {=Nil} -> 0 | I27: {=Nil} -> 0 | ... M27: {=Nil} -> 0 | N27: =SUM(B27:M27) -> 0 | O27: {=Nil} -> 0 | P27: {=Nil} -> 0 | Q27: {=Nil} -> 0 | R27: {=Nil} -> 0 | S27: {=Nil} -> 0 | T27: {=Nil} -> 0 | U27: {=Nil} -> 0 | V27: {=Nil} -> 0 | ... Z27: {=Nil} -> 0 | AA27: =SUM(O27:Z27) -> 0 | AB27: {=Y3_Port_Repair*(Increment-Insurance_Cov)} -> 500000 | AC27: {=Nil} -> 0 | AD27: {=Nil} -> 0
A28: Finance: | AA28: =SUM(O28:Z28) -> 0
A29: Loan Payment | B29: ='Tanker Schedule'!$D$185 -> 0 | C29: ='Tanker Schedule'!$D$185 -> 0 | D29: ='Tanker Schedule'!$D$185 -> 0 | E29: ='Tanker Schedule'!$D$185 -> 0 | F29: ='Tanker Schedule'!$D$185 -> 0 | G29: ='Tanker Schedule'!$D$185 -> 0 | H29: ='Tanker Schedule'!$D$185 -> 0 | I29: ='Tanker Schedule'!$D$185 -> 0 | ... M29: ='Tanker Schedule'!$D$185 -> 0 | N29: =SUM(B29:M29) -> 0 | O29: {=Nil} -> 0 | P29: {=Nil} -> 0 | Q29: {=Nil} -> 0 | R29: {=Nil} -> 0 | S29: {=Nil} -> 0 | T29: {=Nil} -> 0 | U29: {=Nil} -> 0 | V29: {=Nil} -> 0 | ... Y29: {=Nil} -> 0 | Z29: ='Tanker Schedule'!D186 -> 15372204 | AA29: =SUM(O29:Z29) -> 15372204 | AB29: ='Tanker Schedule'!D187 -> 15372204 | AC29: ='Tanker Schedule'!D188 -> 15372204 | AD29: ='Tanker Schedule'!D189 -> 15372204
A30: Total Cash Outflows: | B30: =SUM(B13:B29) -> 20833333 | C30: =SUM(C13:C29) -> 20833333 | D30: =SUM(D13:D29) -> 20833333 | E30: =SUM(E13:E29) -> 20833333 | F30: =SUM(F13:F29) -> 20833333 | G30: =SUM(G13:G29) -> 20833333 | H30: =SUM(H13:H29) -> 20833333 | I30: =SUM(I13:I29) -> 20833333 | ... Z30: =SUM(Z13:Z29) -> 72383497 | AA30: =SUM(AA12:AA29) -> 6.5486987e+08 | AB30: =SUM(AB12:AB29) -> 7.2429573e+08 | AC30: =SUM(AC12:AC29) -> 7.3874304e+08 | AD30: =SUM(AD12:AD29) -> 7.9077104e+08
A32: Change in Cash | B32: =B10-B30 -> 833333.33 | C32: =C10-C30 -> 833333.33 | D32: =D10-D30 -> 833333.33 | E32: =E10-E30 -> 833333.33 | F32: =F10-F30 -> 833333.33 | G32: =G10-G30 -> 833333.33 | H32: =H10-H30 -> 833333.33 | I32: =I10-I30 -> 833333.33 | ... AD32: =AD10-AD30 -> 51161933
A33: Ending Cash Balance | B33: =B7+B32 -> 833333.33 | C33: =C7+C32 -> 1666666.7 | D33: =D7+D32 -> 2500000 | E33: =E7+E32 -> 3333333.3 | F33: =F7+F32 -> 4166666.7 | G33: =G7+G32 -> 5000000 | H33: =H7+H32 -> 5833333.3 | I33: =I7+I32 -> 6666666.7 | ... M33: =M7+M32 -> 10000000 | N33: =M33 -> 10000000 | O33: =O7+O32 -> 70031911 | P33: =P7+P32 -> 72666805 | Q33: =Q7+Q32 -> 85966655 | R33: =R7+R32 -> 92402152 | S33: =S7+S32 -> 1.0271581e+08 | T33: =T7+T32 -> 1.0915131e+08 | U33: =U7+U32 -> 1.1946497e+08 | V33: =V7+V32 -> 1.2807224e+08 | ... Z33: =Z7+Z32 -> 1.4619836e+08 | AA33: =Z33 -> 1.4619836e+08 | AB33: =AB7+AB32 -> 2.3102332e+08 | AC33: =AC7+AC32 -> 3.1764408e+08 | AD33: =AD7+AD32 -> 3.6880601e+08

Sheet Statement of Income
A1: QATAR ENERGY
A2: STATEMENT OF INCOME
A3: FOR THE FINANCIAL YEARS ENDED DECEMBER 31
B5: Year 1 | O5: Year 2 | AB5: Year 3 | AC5: Year 4 | AD5: Year 5
B6: January | C6: February | D6: March | E6: April | F6: May | G6: June | H6: July | I6: August | J6: September | K6: October | L6: November | M6: December | N6: Y1 Total | O6: January | P6: February | Q6: March | R6: April | S6: May | T6: June | U6: July | V6: August | W6: September | X6: October | Y6: November | Z6: December | AA6: Y2 Total
A7: INCOME
A8: Revenues | B8: {=Nil} -> 0 | C8: {=Nil} -> 0 | D8: {=Nil} -> 0 | E8: {=Nil} -> 0 | F8: {=Nil} -> 0 | G8: {=Nil} -> 0 | H8: {=Nil} -> 0 | I8: {=Nil} -> 0 | ... M8: {=Nil} -> 0 | N8: =SUM(B8:M8) -> 0 | O8: {=('Tanker Schedule'!D82/D_i_Y)*Days_Jan} -> 67324956 | P8: {=('Tanker Schedule'!D82/D_i_Y)*Days_Feb} -> 61352580 | Q8: {=('Tanker Schedule'!D82/D_i_Y)*Days_Mar} -> 67324956 | R8: {=('Tanker Schedule'!D82/D_i_Y)*Days_Apr} -> 65153183 | S8: {=('Tanker Schedule'!D82/D_i_Y)*Days_May} -> 67324956 | T8: {=('Tanker Schedule'!D82/D_i_Y)*Days_Jun} -> 65153183 | U8: {=('Tanker Schedule'!D82/D_i_Y)*Days_Jul} -> 67324956 | V8: {=('Tanker Schedule'!D82/D_i_Y)*Days_Aug} -> 67324956 | W8: {=('Tanker Schedule'!D82/D_i_Y)*Days_Sept} -> 65153183 | X8: {=('Tanker Schedule'!D82/D_i_Y)*Days_Oct} -> 67324956 | Y8: {=('Tanker Schedule'!D82/D_i_Y)*Days_Nov} -> 65153183 | Z8: {=('Tanker Schedule'!D82/D_i_Y)*Days_Dec} -> 67324956 | AA8: =SUM(O8:Z8) -> 7.9324e+08 | AB8: ='Tanker Schedule'!D83 -> 8.0916429e+08 | AC8: ='Tanker Schedule'!D84 -> 8.2540827e+08 | AD8: ='Tanker Schedule'!D85 -> 8.4197834e+08
A10: EXPENSES
A11: Operating Costs:
A12: LNG purchases | B12: {=Nil} -> 0 | C12: {=Nil} -> 0 | D12: {=Nil} -> 0 | E12: {=Nil} -> 0 | F12: {=Nil} -> 0 | G12: {=Nil} -> 0 | H12: {=Nil} -> 0 | I12: {=Nil} -> 0 | ... M12: {=Nil} -> 0 | N12: =SUM(B12:M12) -> 0 | O12: {='Tanker Schedule'!I82/D_i_Y*Days_Jan} -> 52898179 | P12: {='Tanker Schedule'!I82/D_i_Y*Days_Feb} -> 48205599 | Q12: {='Tanker Schedule'!I82/D_i_Y*Days_Mar} -> 52898179 | R12: {='Tanker Schedule'!I82/D_i_Y*Days_Apr} -> 51191786 | S12: {='Tanker Schedule'!I82/D_i_Y*Days_May} -> 52898179 | T12: {='Tanker Schedule'!I82/D_i_Y*Days_Jun} -> 51191786 | U12: {='Tanker Schedule'!I82/D_i_Y*Days_Jul} -> 52898179 | V12: {='Tanker Schedule'!I82/D_i_Y*Days_Aug} -> 52898179 | W12: {='Tanker Schedule'!I82/D_i_Y*Days_Sept} -> 51191786 | X12: {='Tanker Schedule'!I82/D_i_Y*Days_Oct} -> 52898179 | Y12: {='Tanker Schedule'!I82/D_i_Y*Days_Nov} -> 51191786 | Z12: {='Tanker Schedule'!I82/D_i_Y*Days_Dec} -> 52898179 | AA12: =SUM(O12:Z12) -> 6.2326e+08 | AB12: ='Tanker Schedule'!I83 -> 6.3577194e+08 | AC12: ='Tanker Schedule'!I84 -> 6.4853507e+08 | AD12: ='Tanker Schedule'!I85 -> 6.6155441e+08
A13: Port fees | B13: {=Nil} -> 0 | C13: {=Nil} -> 0 | D13: {=Nil} -> 0 | E13: {=Nil} -> 0 | F13: {=Nil} -> 0 | G13: {=Nil} -> 0 | H13: {=Nil} -> 0 | I13: {=Nil} -> 0 | ... M13: {=Nil} -> 0 | N13: =SUM(B13:M13) -> 0 | O13: ='Tanker Schedule'!$D$116/M_i_Y -> 1998333.3 | P13: ='Tanker Schedule'!$D$116/M_i_Y -> 1998333.3 | Q13: ='Tanker Schedule'!$D$116/M_i_Y -> 1998333.3 | R13: ='Tanker Schedule'!$D$116/M_i_Y -> 1998333.3 | S13: ='Tanker Schedule'!$D$116/M_i_Y -> 1998333.3 | T13: ='Tanker Schedule'!$D$116/M_i_Y -> 1998333.3 | U13: ='Tanker Schedule'!$D$116/M_i_Y -> 1998333.3 | V13: ='Tanker Schedule'!$D$116/M_i_Y -> 1998333.3 | ... Z13: ='Tanker Schedule'!$D$116/M_i_Y -> 1998333.3 | AA13: =SUM(O13:Z13) -> 23980000 | AB13: ='Tanker Schedule'!D117 -> 24563000 | AC13: ='Tanker Schedule'!D118 -> 25158094 | AD13: ='Tanker Schedule'!D119 -> 25535466
A14: Heavy fuel oil | B14: {=Nil} -> 0 | C14: {=Nil} -> 0 | D14: {=Nil} -> 0 | E14: {=Nil} -> 0 | F14: {=Nil} -> 0 | G14: {=Nil} -> 0 | H14: {=Nil} -> 0 | I14: {=Nil} -> 0 | ... M14: {=Nil} -> 0 | N14: =SUM(B14:M14) -> 0 | O14: ='Tanker Schedule'!$I$116/M_i_Y -> 82840 | P14: ='Tanker Schedule'!$I$116/M_i_Y -> 82840 | Q14: ='Tanker Schedule'!$I$116/M_i_Y -> 82840 | R14: ='Tanker Schedule'!$I$116/M_i_Y -> 82840 | S14: ='Tanker Schedule'!$I$116/M_i_Y -> 82840 | T14: ='Tanker Schedule'!$I$116/M_i_Y -> 82840 | U14: ='Tanker Schedule'!$I$116/M_i_Y -> 82840 | V14: ='Tanker Schedule'!$I$116/M_i_Y -> 82840 | ... Z14: ='Tanker Schedule'!$I$116/M_i_Y -> 82840 | AA14: =SUM(O14:Z14) -> 994080 | AB14: ='Tanker Schedule'!I117 -> 1018248 | AC14: ='Tanker Schedule'!I118 -> 1042917.4 | AD14: ='Tanker Schedule'!I119 -> 1058561.1
A15: Shipping operating costs | B15: {=Nil} -> 0 | C15: {=Nil} -> 0 | D15: {=Nil} -> 0 | E15: {=Nil} -> 0 | F15: {=Nil} -> 0 | G15: {=Nil} -> 0 | H15: {=Nil} -> 0 | I15: {=Nil} -> 0 | ... M15: {=Nil} -> 0 | N15: =SUM(B15:M15) -> 0 | O15: ='Tanker Schedule'!$D$150/M_i_Y -> 363333.33 | P15: ='Tanker Schedule'!$D$150/M_i_Y -> 363333.33 | Q15: ='Tanker Schedule'!$D$150/M_i_Y -> 363333.33 | R15: ='Tanker Schedule'!$D$150/M_i_Y -> 363333.33 | S15: ='Tanker Schedule'!$D$150/M_i_Y -> 363333.33 | T15: ='Tanker Schedule'!$D$150/M_i_Y -> 363333.33 | U15: ='Tanker Schedule'!$D$150/M_i_Y -> 363333.33 | V15: ='Tanker Schedule'!$D$150/M_i_Y -> 363333.33 | ... Z15: ='Tanker Schedule'!$D$150/M_i_Y -> 363333.33 | AA15: =SUM(O15:Z15) -> 4360000 | AB15: ='Tanker Schedule'!D151 -> 4466000 | AC15: ='Tanker Schedule'!D152 -> 4574199 | AD15: ='Tanker Schedule'!D153 -> 4642812
A16: Insurance | B16: {=Nil} -> 0 | C16: {=Nil} -> 0 | D16: {=Nil} -> 0 | E16: {=Nil} -> 0 | F16: {=Nil} -> 0 | G16: {=Nil} -> 0 | H16: {=Nil} -> 0 | I16: {=Nil} -> 0 | ... M16: {=Nil} -> 0 | N16: =SUM(B16:M16) -> 0 | O16: =Insurance_Tanker/M_i_Y -> 150000 | P16: =Insurance_Tanker/M_i_Y -> 150000 | Q16: =Insurance_Tanker/M_i_Y -> 150000 | R16: =Insurance_Tanker/M_i_Y -> 150000 | S16: =Insurance_Tanker/M_i_Y -> 150000 | T16: =Insurance_Tanker/M_i_Y -> 150000 | U16: =Insurance_Tanker/M_i_Y -> 150000 | V16: =Insurance_Tanker/M_i_Y -> 150000 | ... Z16: =Insurance_Tanker/M_i_Y -> 150000 | AA16: =SUM(O16:Z16) -> 1800000 | AB16: =AA16*(Increment+Inflation_Annual) -> 1827000 | AC16: =AB16*(Increment+Inflation_Annual) -> 1854405 | AD16: =AC16*(Increment+Inflation_Annual) -> 1882221.1
A17: Payroll - Payments to Employees | B17: {=Nil} -> 0 | C17: {=Nil} -> 0 | D17: {=Nil} -> 0 | E17: {=Nil} -> 0 | F17: {=Nil} -> 0 | G17: {=Nil} -> 0 | H17: {=Nil} -> 0 | I17: {=Nil} -> 0 | ... M17: {=Nil} -> 0 | N17: =SUM(B17:M17) -> 0 | O17: ='Tanker Schedule'!$H$48 -> 237938.6 | P17: ='Tanker Schedule'!$H$48 -> 237938.6 | Q17: ='Tanker Schedule'!$H$48 -> 237938.6 | R17: ='Tanker Schedule'!$H$48 -> 237938.6 | S17: ='Tanker Schedule'!$H$48 -> 237938.6 | T17: ='Tanker Schedule'!$H$48 -> 237938.6 | U17: ='Tanker Schedule'!$H$48 -> 237938.6 | V17: ='Tanker Schedule'!$H$48 -> 237938.6 | ... Z17: ='Tanker Schedule'!$H$48 -> 237938.6 | AA17: =SUM(O17:Z17) -> 2855263.2 | AB17: ='Tanker Schedule'!F49 -> 2898092.1 | AC17: ='Tanker Schedule'!F50 -> 2941563.5 | AD17: ='Tanker Schedule'!F51 -> 2985686.9
A18: Payroll - Remittance to Government | B18: {=Nil} -> 0 | C18: {=Nil} -> 0 | D18: {=Nil} -> 0 | E18: {=Nil} -> 0 | F18: {=Nil} -> 0 | G18: {=Nil} -> 0 | H18: {=Nil} -> 0 | I18: {=Nil} -> 0 | ... M18: {=Nil} -> 0 | N18: =SUM(B18:M18) -> 0 | O18: ='Tanker Schedule'!$I$48 -> 53728.07 | P18: ='Tanker Schedule'!$I$48 -> 53728.07 | Q18: ='Tanker Schedule'!$I$48 -> 53728.07 | R18: ='Tanker Schedule'!$I$48 -> 53728.07 | S18: ='Tanker Schedule'!$I$48 -> 53728.07 | T18: ='Tanker Schedule'!$I$48 -> 53728.07 | U18: ='Tanker Schedule'!$I$48 -> 53728.07 | V18: ='Tanker Schedule'!$I$48 -> 53728.07 | ... Z18: ='Tanker Schedule'!$I$48 -> 53728.07 | AA18: =SUM(O18:Z18) -> 644736.84 | AB18: ='Tanker Schedule'!G49 -> 654407.89 | AC18: ='Tanker Schedule'!G50 -> 664224.01 | AD18: ='Tanker Schedule'!G51 -> 674187.37
A19: Maintenance and Engineering | B19: {=Nil} -> 0 | C19: {=Nil} -> 0 | D19: {=Nil} -> 0 | E19: {=Nil} -> 0 | F19: {=Nil} -> 0 | G19: {=Nil} -> 0 | H19: {=Nil} -> 0 | I19: {=Nil} -> 0 | ... M19: {=Nil} -> 0 | N19: =SUM(B19:M19) -> 0 | O19: =General_Tanker/M_i_Y -> 166666.67 | P19: =General_Tanker/M_i_Y -> 166666.67 | Q19: =General_Tanker/M_i_Y -> 166666.67 | R19: =General_Tanker/M_i_Y -> 166666.67 | S19: =General_Tanker/M_i_Y -> 166666.67 | T19: =General_Tanker/M_i_Y -> 166666.67 | U19: =General_Tanker/M_i_Y -> 166666.67 | V19: =General_Tanker/M_i_Y -> 166666.67 | ... Z19: =General_Tanker/M_i_Y -> 166666.67 | AA19: =SUM(O19:Z19) -> 2000000 | AB19: =AA19*(Increment+Inflation_Annual) -> 2030000 | AC19: =AB19*(Increment+Inflation_Annual) -> 2060450 | AD19: =AC19*(Increment+Inflation_Annual) -> 2091356.7
A20: Stores, spares, lubricants | B20: {=Nil} -> 0 | C20: {=Nil} -> 0 | D20: {=Nil} -> 0 | E20: {=Nil} -> 0 | F20: {=Nil} -> 0 | G20: {=Nil} -> 0 | H20: {=Nil} -> 0 | I20: {=Nil} -> 0 | ... M20: {=Nil} -> 0 | N20: =SUM(B20:M20) -> 0 | O20: =Stores_Spares_Lube/M_i_Y -> 166666.67 | P20: =Stores_Spares_Lube/M_i_Y -> 166666.67 | Q20: =Stores_Spares_Lube/M_i_Y -> 166666.67 | R20: =Stores_Spares_Lube/M_i_Y -> 166666.67 | S20: =Stores_Spares_Lube/M_i_Y -> 166666.67 | T20: =Stores_Spares_Lube/M_i_Y -> 166666.67 | U20: =Stores_Spares_Lube/M_i_Y -> 166666.67 | V20: =Stores_Spares_Lube/M_i_Y -> 166666.67 | ... Z20: =Stores_Spares_Lube/M_i_Y -> 166666.67 | AA20: =SUM(O20:Z20) -> 2000000 | AB20: =AA20*(Increment+Inflation_Annual) -> 2030000 | AC20: =AB20*(Increment+Inflation_Annual) -> 2060450 | AD20: =AC20*(Increment+Inflation_Annual) -> 2091356.7
A21: Carbon offsets | B21: {=Nil} -> 0 | C21: {=Nil} -> 0 | D21: {=Nil} -> 0 | E21: {=Nil} -> 0 | F21: {=Nil} -> 0 | G21: {=Nil} -> 0 | H21: {=Nil} -> 0 | I21: {=Nil} -> 0 | ... M21: {=Nil} -> 0 | N21: =SUM(B21:M21) -> 0 | O21: =Carbon_Offset_Tanker/M_i_Y -> 2750000 | P21: =Carbon_Offset_Tanker/M_i_Y -> 2750000 | Q21: =Carbon_Offset_Tanker/M_i_Y -> 2750000 | R21: =Carbon_Offset_Tanker/M_i_Y -> 2750000 | S21: =Carbon_Offset_Tanker/M_i_Y -> 2750000 | T21: =Carbon_Offset_Tanker/M_i_Y -> 2750000 | U21: =Carbon_Offset_Tanker/M_i_Y -> 2750000 | V21: =Carbon_Offset_Tanker/M_i_Y -> 2750000 | ... Z21: =Carbon_Offset_Tanker/M_i_Y -> 2750000 | AA21: =SUM(O21:Z21) -> 33000000 | AB21: =AA21*(Increment+Inflation_Carbon_Offset) -> 34287000 | AC21: =AB21*(Increment+Inflation_Carbon_Offset) -> 35624193 | AD21: {=AC21*(Increment+Inflation_Carbon_Offset)*Y5_Carbon_Increase} -> 74027073
A22: Special Events Costs:
A23: Port damage | B23: {=Nil} -> 0 | C23: {=Nil} -> 0 | D23: {=Nil} -> 0 | E23: {=Nil} -> 0 | F23: {=Nil} -> 0 | G23: {=Nil} -> 0 | H23: {=Nil} -> 0 | I23: {=Nil} -> 0 | ... M23: {=Nil} -> 0 | N23: =SUM(B23:M23) -> 0 | O23: {=Nil} -> 0 | P23: {=Nil} -> 0 | Q23: {=Nil} -> 0 | R23: {=Nil} -> 0 | S23: {=Nil} -> 0 | T23: {=Nil} -> 0 | U23: {=Nil} -> 0 | V23: {=Nil} -> 0 | ... Z23: {=Nil} -> 0 | AA23: =SUM(O23:Z23) -> 0 | AB23: {=Y3_Port_Repair} -> 5000000 | AC23: {=Nil} -> 0 | AD23: {=Nil} -> 0
A24: Insruance payout | B24: {=Nil} -> 0 | C24: {=Nil} -> 0 | D24: {=Nil} -> 0 | E24: {=Nil} -> 0 | F24: {=Nil} -> 0 | G24: {=Nil} -> 0 | H24: {=Nil} -> 0 | I24: {=Nil} -> 0 | ... M24: {=Nil} -> 0 | N24: =SUM(B24:M24) -> 0 | O24: {=Nil} -> 0 | P24: {=Nil} -> 0 | Q24: {=Nil} -> 0 | R24: {=Nil} -> 0 | S24: {=Nil} -> 0 | T24: {=Nil} -> 0 | U24: {=Nil} -> 0 | V24: {=Nil} -> 0 | ... Z24: {=Nil} -> 0 | AA24: =SUM(O24:Z24) -> 0 | AB24: {=-Y3_Port_Repair*Insurance_Cov} -> -4500000 | AC24: {=Nil} -> 0 | AD24: {=Nil} -> 0
A25: TOTAL EXPENSES | B25: =SUM(B12:B24) -> 0 | C25: =SUM(C12:C24) -> 0 | D25: =SUM(D12:D24) -> 0 | E25: =SUM(E12:E24) -> 0 | F25: =SUM(F12:F24) -> 0 | G25: =SUM(G12:G24) -> 0 | H25: =SUM(H12:H24) -> 0 | I25: =SUM(I12:I24) -> 0 | ... AD25: =SUM(AD12:AD24) -> 7.7654313e+08
A27: EBITDA | B27: =B8-B25 -> 0 | C27: =C8-C25 -> 0 | D27: =D8-D25 -> 0 | E27: =E8-E25 -> 0 | F27: =F8-F25 -> 0 | G27: =G8-G25 -> 0 | H27: =H8-H25 -> 0 | I27: =I8-I25 -> 0 | ... AD27: =AD8-AD25 -> 65435208
A29: Interest | B29: {=TRANSPOSE('Tanker Schedule'!J185:J196)} -> 102777.78 | C29: 172222.22 | D29: 241666.67 | E29: 311111.11 | F29: 380555.56 | G29: 450000 | H29: 519444.44 | I29: 588888.89 | J29: 658333.33 | K29: 727777.78 | L29: 797222.22 | M29: 866666.67 | N29: =SUM(B29:M29) -> 5816666.7 | O29: ='Tanker Schedule'!$C$186/M_i_Y -> 886055.56 | P29: ='Tanker Schedule'!$C$186/M_i_Y -> 886055.56 | Q29: ='Tanker Schedule'!$C$186/M_i_Y -> 886055.56 | R29: ='Tanker Schedule'!$C$186/M_i_Y -> 886055.56 | S29: ='Tanker Schedule'!$C$186/M_i_Y -> 886055.56 | T29: ='Tanker Schedule'!$C$186/M_i_Y -> 886055.56 | U29: ='Tanker Schedule'!$C$186/M_i_Y -> 886055.56 | V29: ='Tanker Schedule'!$C$186/M_i_Y -> 886055.56 | ... Z29: ='Tanker Schedule'!$C$186/M_i_Y -> 886055.56 | AA29: =SUM(O29:Z29) -> 10632667 | AB29: ='Tanker Schedule'!C187 -> 10443085 | AC29: ='Tanker Schedule'!C188 -> 10245920 | AD29: ='Tanker Schedule'!C189 -> 10040869
A30: Depreciation | B30: {=Nil} -> 0 | C30: {=Nil} -> 0 | D30: {=Nil} -> 0 | E30: {=Nil} -> 0 | F30: {=Nil} -> 0 | G30: {=Nil} -> 0 | H30: {=Nil} -> 0 | I30: {=Nil} -> 0 | ... M30: {=Nil} -> 0 | N30: =SUM(B30:M30) -> 0 | O30: ='Tanker Schedule'!$C$14/M_i_Y -> 638888.89 | P30: ='Tanker Schedule'!$C$14/M_i_Y -> 638888.89 | Q30: ='Tanker Schedule'!$C$14/M_i_Y -> 638888.89 | R30: ='Tanker Schedule'!$C$14/M_i_Y -> 638888.89 | S30: ='Tanker Schedule'!$C$14/M_i_Y -> 638888.89 | T30: ='Tanker Schedule'!$C$14/M_i_Y -> 638888.89 | U30: ='Tanker Schedule'!$C$14/M_i_Y -> 638888.89 | V30: ='Tanker Schedule'!$C$14/M_i_Y -> 638888.89 | ... Z30: ='Tanker Schedule'!$C$14/M_i_Y -> 638888.89 | AA30: =SUM(O30:Z30) -> 7666666.7 | AB30: ='Tanker Schedule'!C15 -> 7666666.7 | AC30: ='Tanker Schedule'!C16 -> 7666666.7 | AD30: ='Tanker Schedule'!C17 -> 7666666.7
A32: NET INCOME | B32: =B27-B29-B30 -> -102777.78 | C32: =C27-C29-C30 -> -172222.22 | D32: =D27-D29-D30 -> -241666.67 | E32: =E27-E29-E30 -> -311111.11 | F32: =F27-F29-F30 -> -380555.56 | G32: =G27-G29-G30 -> -450000 | H32: =H27-H29-H30 -> -519444.44 | I32: =I27-I29-I30 -> -588888.89 | ... AD32: =AD27-AD29-AD30 -> 47727673

Sheet Statement of Financial Position
A1: QATAR ENERGY
A2: STATEMENT OF FINANCIAL POSITION
A3: FOR THE FINANCIAL YEARS ENDED DECEMBER 31
B5: Year 1 | C5: Year 2 | D5: Year 3 | E5: Year 4 | F5: Year 5
A6: ASSETS
A8: Cash | B8: ='Cash Budget'!N33 -> 10000000 | C8: ='Cash Budget'!AA33 -> 1.4619836e+08 | D8: ='Cash Budget'!AB33 -> 2.3102332e+08 | E8: ='Cash Budget'!AC33 -> 3.1764408e+08 | F8: ='Cash Budget'!AD33 -> 3.6880601e+08
A9: Accounts Receivable | C9: ='Tanker Schedule'!D82/D_i_Y -> 2171772.8 | D9: ='Tanker Schedule'!D83/D_i_Y -> 2215371.1 | E9: ='Tanker Schedule'!D84/D_i_Y -> 2259844.7 | F9: ='Tanker Schedule'!D85/D_i_Y -> 2305211.1
A10: Fixed Assets | B10: =Building_Cost_Tanker -> 250000000 | C10: =Building_Cost_Tanker -> 250000000 | D10: =Building_Cost_Tanker -> 250000000 | E10: =Building_Cost_Tanker -> 250000000 | F10: =Building_Cost_Tanker -> 250000000
A11: less Accumulated Depreciation | C11: =-(Annual_Depreciation_Tanker) -> -7666666.7 | D11: =-(Annual_Depreciation_Tanker-C11) -> -15333333 | E11: =-(Annual_Depreciation_Tanker-D11) -> -23000000 | F11: =-(Annual_Depreciation_Tanker-E11) -> -30666667
A13: TOTAL ASSETS | B13: =SUM(B8:B11) -> 2.6e+08 | C13: =SUM(C8:C11) -> 3.9070346e+08 | D13: =SUM(D8:D11) -> 4.6790536e+08 | E13: =SUM(E8:E11) -> 5.4690392e+08 | F13: =SUM(F8:F11) -> 5.9044456e+08
A15: LIABILITES
A17: Employer Remittance Payable | C17: ='Tanker Schedule'!I48 -> 53728.07 | D17: ='Tanker Schedule'!I49 -> 54533.991 | E17: ='Tanker Schedule'!I50 -> 55352.001 | F17: ='Tanker Schedule'!I51 -> 56182.281
A18: LNG Payable | C18: {=('Tanker Schedule'!I82/D_i_Y)*Days_Dec} -> 52898179 | D18: {=('Tanker Schedule'!I83/D_i_Y)*Days_Dec} -> 53960110 | E18: {=('Tanker Schedule'!I84/D_i_Y)*Days_Dec} -> 55043359 | F18: {=('Tanker Schedule'!I85/D_i_Y)*Days_Dec} -> 56148355
A19: Port Fees Payable | C19: ='Tanker Schedule'!D116/M_i_Y -> 1998333.3 | D19: ='Tanker Schedule'!D117/M_i_Y -> 2046916.7 | E19: ='Tanker Schedule'!D118/M_i_Y -> 2096507.9 | F19: ='Tanker Schedule'!D119/M_i_Y -> 2127955.5
A20: Heavy Fuel Oil Payable | C20: ='Tanker Schedule'!I116/M_i_Y -> 82840 | D20: ='Tanker Schedule'!I117/M_i_Y -> 84854 | E20: ='Tanker Schedule'!I118/M_i_Y -> 86909.781 | F20: ='Tanker Schedule'!I119/M_i_Y -> 88213.428
A21: Shipping Operating Expense Payable | C21: ='Tanker Schedule'!D150/M_i_Y -> 363333.33 | D21: ='Tanker Schedule'!D151/M_i_Y -> 372166.67 | E21: ='Tanker Schedule'!D152/M_i_Y -> 381183.25 | F21: ='Tanker Schedule'!D153/M_i_Y -> 386901
A22: Bank Loan O/S | B22: ='Tanker Schedule'!F185 -> 2.6581667e+08 | C22: ='Tanker Schedule'!F186 -> 2.6107713e+08 | D22: ='Tanker Schedule'!F187 -> 2.5614801e+08 | E22: ='Tanker Schedule'!F188 -> 2.5102173e+08 | F22: ='Tanker Schedule'!F189 -> 2.4569039e+08
A24: SHAREHOLDERS EQUITY
A26: Retained Earnings | B26: ='Statement of Income'!N32 -> -5816666.7 | C26: ='Statement of Income'!AA32+B26 -> 74229920 | D26: ='Statement of Income'!AB32+C26 -> 1.5523877e+08 | E26: ='Statement of Income'!AC32+D26 -> 2.3821889e+08 | F26: ='Statement of Income'!AD32+E26 -> 2.8594656e+08
A28: TOTAL LIABILITES AND SHAREHOLDERS EQUITY | B28: =SUM(B17:B26) -> 260000000 | C28: =SUM(C17:C26) -> 3.9070346e+08 | D28: =SUM(D17:D26) -> 4.6790536e+08 | E28: =SUM(E17:E26) -> 5.4690392e+08 | F28: =SUM(F17:F26) -> 5.9044456e+08
A30: Check Sum | B30: =B13-B28 -> 0 | C30: =C13-C28 -> 0 | D30: =D13-D28 -> 0 | E30: =E13-E28 -> 0 | F30: =F13-F28 -> 0

Sheet NPV (Y2-Y31)
A1: QATAR ENERGY
A2: 30-YR NPV COMPARISON (PIPELINE Vs. TANKER)
A4: CASH FLOW - PIPELINE
B5: Y2 | C5: Y3 | D5: Y4 | E5: Y5 | F5: Y6 | G5: Y7 | H5: Y8 | I5: Y9 | J5: Y10 | K5: Y11 | L5: Y12 | M5: Y13 | N5: Y14 | O5: Y15 | P5: Y16 | Q5: Y17 | R5: Y18 | S5: Y19 | T5: Y20 | U5: Y21 | V5: Y22 | W5: Y23 | X5: Y24 | Y5: Y25 | Z5: Y26 | AA5: Y27 | AB5: Y28 | AC5: Y29 | AD5: Y30 | AE5: Y31
A6: Revenue:
A7: Sales | B7: {=TRANSPOSE('Pipeline Schedule'!D49:D78)} -> 884000000 | C7: 9.017463e+08 | D7: 9.1984886e+08 | E7: 9.3831482e+08 | F7: 9.5715149e+08 | G7: 9.7636631e+08 | H7: 9.9596686e+08 | I7: 1.0159609e+09 | J7: 1.0363563e+09 | K7: 1.0571612e+09 | L7: 1.0783837e+09 | M7: 1.1000322e+09 | N7: 1.1221154e+09 | O7: 1.1446418e+09 | P7: 1.1676205e+09 | Q7: 1.1910605e+09 | R7: 1.214971e+09 | S7: 1.2393616e+09 | T7: 1.2642418e+09 | U7: 1.2896214e+09 | V7: 1.3155106e+09 | W7: 1.3419195e+09 | X7: 1.3688585e+09 | Y7: 1.3963383e+09 | Z7: 1.4243698e+09 | AA7: 1.452964e+09 | AB7: 1.4821323e+09 | AC7: 1.5118861e+09 | AD7: 1.5422372e+09 | AE7: 1.5731976e+09
A8: Less: COGS | B8: {=TRANSPOSE('Pipeline Schedule'!I49:I78)} -> 782000000 | C8: 7.9769865e+08 | D8: 8.1371245e+08 | E8: 8.3004773e+08 | F8: 8.4671094e+08 | G8: 8.6370866e+08 | H8: 8.8104761e+08 | I8: 8.9873464e+08 | J8: 9.1677674e+08 | K8: 9.3518103e+08 | L8: 9.5395479e+08 | M8: 9.7310543e+08 | N8: 9.9264052e+08 | O8: 1.0125678e+09 | P8: 1.0328951e+09 | Q8: 1.0536304e+09 | R8: 1.0747821e+09 | S8: 1.0963583e+09 | T8: 1.1183677e+09 | U8: 1.140819e+09 | V8: 1.1637209e+09 | W8: 1.1870826e+09 | X8: 1.2109133e+09 | Y8: 1.2352224e+09 | Z8: 1.2600195e+09 | AA8: 1.2853143e+09 | AB8: 1.311117e+09 | AC8: 1.3374377e+09 | AD8: 1.3642868e+09 | AE8: 1.3916748e+09
A9: Salvage Value | B9: {=Nil} -> 0 | C9: {=Nil} -> 0 | D9: {=Nil} -> 0 | E9: {=Nil} -> 0 | F9: {=Nil} -> 0 | G9: {=Nil} -> 0 | H9: {=Nil} -> 0 | I9: {=Nil} -> 0 | ... AD9: {=Nil} -> 0 | AE9: =Salvage_Val_Pipeline -> 15000000
A10: Total | B10: =B7-B8+B9 -> 102000000 | C10: =C7-C8+C9 -> 1.0404765e+08 | D10: =D7-D8+D9 -> 1.0613641e+08 | E10: =E7-E8+E9 -> 1.0826709e+08 | F10: =F7-F8+F9 -> 1.1044056e+08 | G10: =G7-G8+G9 -> 1.1265765e+08 | H10: =H7-H8+H9 -> 1.1491925e+08 | I10: =I7-I8+I9 -> 1.1722626e+08 | ... AE10: =AE7-AE8+AE9 -> 1.965228e+08
A12: Expenses:
A13: Insurance | B13: =Insurance_Pipeline -> 2200000 | C13: =B13*(Increment+Inflation_Annual) -> 2233000 | D13: =C13*(Increment+Inflation_Annual) -> 2266495 | E13: =D13*(Increment+Inflation_Annual) -> 2300492.4 | F13: =E13*(Increment+Inflation_Annual) -> 2334999.8 | G13: =F13*(Increment+Inflation_Annual) -> 2370024.8 | H13: =G13*(Increment+Inflation_Annual) -> 2405575.2 | I13: =H13*(Increment+Inflation_Annual) -> 2441658.8 | J13: =I13*(Increment+Inflation_Annual) -> 2478283.7 | ... AE13: =AD13*(Increment+Inflation_Annual) -> 3387957.1
A14: Operatings Management | B14: =Operations_Mgmt -> 1000000 | C14: =B14*(Increment+Inflation_Annual) -> 1015000 | D14: =C14*(Increment+Inflation_Annual) -> 1030225 | E14: =D14*(Increment+Inflation_Annual) -> 1045678.4 | F14: =E14*(Increment+Inflation_Annual) -> 1061363.6 | G14: =F14*(Increment+Inflation_Annual) -> 1077284 | H14: =G14*(Increment+Inflation_Annual) -> 1093443.3 | I14: =H14*(Increment+Inflation_Annual) -> 1109844.9 | J14: =I14*(Increment+Inflation_Annual) -> 1126492.6 | ... AE14: =AD14*(Increment+Inflation_Annual) -> 1539980.5
